1. After "throw;",there isn't any "catch",so the function just terminates.

2. YES.
After "throw","catch" can catch 3.0 because it's a float ,so it can handle the exception.
After handling the excpetion,the function will go on,so "I love C++" will show.

3.
how to compile: make
running script:
命令稿啟動於 2016年06月13日 上午 09:07:16
]0;~
[32muser@user-PC [33m~[0m
$ M[Kmake
g++ -c tetris5.cpp
g++ -c Mino.cpp
g++ -c MinoS.cpp
g++ -c MinoI.cpp	
g++ -c MinoL.cpp	
g++ -c MinoO.cpp	
g++ -c MinoT.cpp
g++ -c genMino.cpp
g++ -o tetris5 tetris5.o Mino.o MinoS.o MinoI.o MinoL.o MinoO.o MinoT.o genMino.o
]0;~
[32muser@user-PC [33m~[0m
$ ./tertis5[C[1Pis5[1Pis5tis5ris5
memory insufficient!!
]0;~
[32muser@user-PC [33m~[0m
$ exit

命令稿已於 2016年06月13日 上午 09:21:34
 完成
